Workbook

Sheet Lees mij
A1: Reconciliatie wekelijks sales-rapport ↔ finance, Q3 2026
A2: Vennaert (fictief bedrijf) · illustratieve cijfers, geen echte bedrijfsdata
A4: Vraag van de sales manager: 'Waarom zegt ons Excel-rapport meer omzet dan finance?'
A6: Werkwijze
A7: 1. Tab Export = de ruwe export waarop het wekelijkse rapport gebouwd is (gesorteerd op datum, factuur, artikel).
A8: 2. Hulpkolommen G–J classificeren elke rij: soort document, dubbele rij, interne klant, netto bedrag met teken.
A9: 3. Tab Brug zet het rapporttotaal stap voor stap om naar het finance-cijfer. Elke stap is een SUMIFS op Export.
A10: 4. Kolom Controle vergelijkt elke stap met de SQL-pipeline (sql/05_reconciliation.sql). OK = beide tellen hetzelfde.
A11: 5. Tab Per verkoper = draaitabel met formules (netto per verkoper per maand). Echte draaitabel: Invoegen > Draaitabel op tabel tExport.
A13: Conclusie
A14: Het rapport telt creditnota's op in plaats van ze af te trekken, bevat één dag twee keer en rekent de personeelsshop mee.
A15: Na die drie correcties is het verschil met finance € 0,00. De nieuwe Power BI-rapportering gebruikt de finance-definitie (KPI-01).

Sheet Export
A1: Datum | B1: Factuur | C1: Klant | D1: Artikel | E1: Verkoper | F1: Bedrag | G1: Soort | H1: Dubbel | I1: Intern | J1: Netto
A2: 2026-07-01 | B2: C900348 | C2: C11363 | D2: SKU-10326 | E2: AM09 | F2: 35.55 | G2: =IF(LEFT(B2,1)="C","Credit","Factuur") | H2: 0 | I2: =IF(C2="C99999",1,0) | J2: =IF(OR(H2=1,I2=1),0,IF(G2="Credit",-F2,F2))
A3: 2026-07-01 | B3: C901944 | C3: C10756 | D3: SKU-10153 | E3: AM06 | F3: 134.88 | G3: =IF(LEFT(B3,1)="C","Credit","Factuur") | H3: =IF(AND(B3=B2,D3=D2,A3=A2,F3=F2),1,0) | I3: =IF(C3="C99999",1,0) | J3: =IF(OR(H3=1,I3=1),0,IF(G3="Credit",-F3,F3))
A4: 2026-07-01 | B4: C902040 | C4: C11259 | D4: SKU-10284 | E4: AM08 | F4: 647.14 | G4: =IF(LEFT(B4,1)="C","Credit","Factuur") | H4: =IF(AND(B4=B3,D4=D3,A4=A3,F4=F3),1,0) | I4: =IF(C4="C99999",1,0) | J4: =IF(OR(H4=1,I4=1),0,IF(G4="Credit",-F4,F4))
A5: 2026-07-01 | B5: F260308 | C5: C10019 | D5: SKU-10169 | E5: AM02 | F5: 216.02 | G5: =IF(LEFT(B5,1)="C","Credit","Factuur") | H5: =IF(AND(B5=B4,D5=D4,A5=A4,F5=F4),1,0) | I5: =IF(C5="C99999",1,0) | J5: =IF(OR(H5=1,I5=1),0,IF(G5="Credit",-F5,F5))
A6: 2026-07-01 | B6: F260308 | C6: C10019 | D6: SKU-10206 | E6: AM02 | F6: 202.56 | G6: =IF(LEFT(B6,1)="C","Credit","Factuur") | H6: =IF(AND(B6=B5,D6=D5,A6=A5,F6=F5),1,0) | I6: =IF(C6="C99999",1,0) | J6: =IF(OR(H6=1,I6=1),0,IF(G6="Credit",-F6,F6))
A7: 2026-07-01 | B7: F260612 | C7: C10034 | D7: SKU-10053 | E7: AM08 | F7: 225 | G7: =IF(LEFT(B7,1)="C","Credit","Factuur") | H7: =IF(AND(B7=B6,D7=D6,A7=A6,F7=F6),1,0) | I7: =IF(C7="C99999",1,0) | J7: =IF(OR(H7=1,I7=1),0,IF(G7="Credit",-F7,F7))
A8: 2026-07-01 | B8: F260612 | C8: C10034 | D8: SKU-10099 | E8: AM08 | F8: 232.96 | G8: =IF(LEFT(B8,1)="C","Credit","Factuur") | H8: =IF(AND(B8=B7,D8=D7,A8=A7,F8=F7),1,0) | I8: =IF(C8="C99999",1,0) | J8: =IF(OR(H8=1,I8=1),0,IF(G8="Credit",-F8,F8))
A9: 2026-07-01 | B9: F260612 | C9: C10034 | D9: SKU-10258 | E9: AM08 | F9: 222.17 | G9: =IF(LEFT(B9,1)="C","Credit","Factuur") | H9: =IF(AND(B9=B8,D9=D8,A9=A8,F9=F8),1,0) | I9: =IF(C9="C99999",1,0) | J9: =IF(OR(H9=1,I9=1),0,IF(G9="Credit",-F9,F9))
A10: 2026-07-01 | B10: F260658 | C10: C10037 | D10: SKU-10116 | E10: AM03 | F10: 651 | G10: =IF(LEFT(B10,1)="C","Credit","Factuur") | H10: =IF(AND(B10=B9,D10=D9,A10=A9,F10=F9),1,0) | I10: =IF(C10="C99999",1,0) | J10: =IF(OR(H10=1,I10=1),0,IF(G10="Credit",-F10,F10))
A11: 2026-07-01 | B11: F260838 | C11: C10049 | D11: SKU-10055 | E11: AM09 | F11: 4045.39 | G11: =IF(LEFT(B11,1)="C","Credit","Factuur") | H11: =IF(AND(B11=B10,D11=D10,A11=A10,F11=F10),1,0) | I11: =IF(C11="C99999",1,0) | J11: =IF(OR(H11=1,I11=1),0,IF(G11="Credit",-F11,F11))
A12: 2026-07-01 | B12: F260838 | C12: C10049 | D12: SKU-10289 | E12: AM09 | F12: 4048.23 | G12: =IF(LEFT(B12,1)="C","Credit","Factuur") | H12: =IF(AND(B12=B11,D12=D11,A12=A11,F12=F11),1,0) | I12: =IF(C12="C99999",1,0) | J12: =IF(OR(H12=1,I12=1),0,IF(G12="Credit",-F12,F12))
A13: 2026-07-01 | B13: F264044 | C13: C10212 | D13: SKU-10322 | E13: AM11 | F13: 2819.44 | G13: =IF(LEFT(B13,1)="C","Credit","Factuur") | H13: =IF(AND(B13=B12,D13=D12,A13=A12,F13=F12),1,0) | I13: =IF(C13="C99999",1,0) | J13: =IF(OR(H13=1,I13=1),0,IF(G13="Credit",-F13,F13))
A14: 2026-07-01 | B14: F264195 | C14: C10221 | D14: SKU-10093 | E14: AM06 | F14: 193.78 | G14: =IF(LEFT(B14,1)="C","Credit","Factuur") | H14: =IF(AND(B14=B13,D14=D13,A14=A13,F14=F13),1,0) | I14: =IF(C14="C99999",1,0) | J14: =IF(OR(H14=1,I14=1),0,IF(G14="Credit",-F14,F14))
... A111: 2026-07-02 | B111: F265754 | C111: C10300 | D111: SKU-10121 | E111: AM03 | F111: 259.72 | G111: =IF(LEFT(B111,1)="C","Credit","Factuur") | H111: =IF(AND(B111=B110,D111=D110,A111=A110,F111=F110),1,0) | I111: =IF(C111="C99999",1,0) | J111: =IF(OR(H111=1,I111=1),0,IF(G111="Credit",-F111,F111))
A112: 2026-07-02 | B112: F265754 | C112: C10300 | D112: SKU-10269 | F112: 230.88 | G112: =IF(LEFT(B112,1)="C","Credit","Factuur") | H112: =IF(AND(B112=B111,D112=D111,A112=A111,F112=F111),1,0) | I112: =IF(C112="C99999",1,0) | J112: =IF(OR(H112=1,I112=1),0,IF(G112="Credit",-F112,F112))
A113: 2026-07-02 | B113: F265754 | C113: C10300 | D113: SKU-10326 | E113: AM03 | F113: 237 | G113: =IF(LEFT(B113,1)="C","Credit","Factuur") | H113: =IF(AND(B113=B112,D113=D112,A113=A112,F113=F112),1,0) | I113: =IF(C113="C99999",1,0) | J113: =IF(OR(H113=1,I113=1),0,IF(G113="Credit",-F113,F113))
A114: 2026-07-02 | B114: F266436 | C114: C10338 | D114: SKU-10039 | E114: AM05 | F114: 875.61 | G114: =IF(LEFT(B114,1)="C","Credit","Factuur") | H114: =IF(AND(B114=B113,D114=D113,A114=A113,F114=F113),1,0) | I114: =IF(C114="C99999",1,0) | J114: =IF(OR(H114=1,I114=1),0,IF(G114="Credit",-F114,F114))
A115: 2026-07-02 | B115: F268681 | C115: C10454 | D115: SKU-10121 | E115: AM12 | F115: 185.05 | G115: =IF(LEFT(B115,1)="C","Credit","Factuur") | H115: =IF(AND(B115=B114,D115=D114,A115=A114,F115=F114),1,0) | I115: =IF(C115="C99999",1,0) | J115: =IF(OR(H115=1,I115=1),0,IF(G115="Credit",-F115,F115))
A116: 2026-07-02 | B116: F268681 | C116: C10454 | D116: SKU-10255 | E116: AM12 | F116: 181.74 | G116: =IF(LEFT(B116,1)="C","Credit","Factuur") | H116: =IF(AND(B116=B115,D116=D115,A116=A115,F116=F115),1,0) | I116: =IF(C116="C99999",1,0) | J116: =IF(OR(H116=1,I116=1),0,IF(G116="Credit",-F116,F116))
A117: 2026-07-02 | B117: F268681 | C117: C10454 | D117: SKU-10340 | E117: AM12 | F117: 179.66 | G117: =IF(LEFT(B117,1)="C","Credit","Factuur") | H117: =IF(AND(B117=B116,D117=D116,A117=A116,F117=F116),1,0) | I117: =IF(C117="C99999",1,0) | J117: =IF(OR(H117=1,I117=1),0,IF(G117="Credit",-F117,F117))
A118: 2026-07-02 | B118: F269909 | C118: C10522 | D118: SKU-10310 | E118: AM11 | F118: 201.51 | G118: =IF(LEFT(B118,1)="C","Credit","Factuur") | H118: =IF(AND(B118=B117,D118=D117,A118=A117,F118=F117),1,0) | I118: =IF(C118="C99999",1,0) | J118: =IF(OR(H118=1,I118=1),0,IF(G118="Credit",-F118,F118))
A119: 2026-07-02 | B119: F269909 | C119: C10522 | D119: SKU-10339 | E119: AM11 | F119: 210.7 | G119: =IF(LEFT(B119,1)="C","Credit","Factuur") | H119: =IF(AND(B119=B118,D119=D118,A119=A118,F119=F118),1,0) | I119: =IF(C119="C99999",1,0) | J119: =IF(OR(H119=1,I119=1),0,IF(G119="Credit",-F119,F119))
A120: 2026-07-02 | B120: F271619 | C120: C10598 | D120: SKU-10057 | E120: AM03 | F120: 225 | G120: =IF(LEFT(B120,1)="C","Credit","Factuur") | H120: =IF(AND(B120=B119,D120=D119,A120=A119,F120=F119),1,0) | I120: =IF(C120="C99999",1,0) | J120: =IF(OR(H120=1,I120=1),0,IF(G120="Credit",-F120,F120))
A121: 2026-07-02 | B121: F271988 | C121: C10617 | D121: SKU-10125 | E121: AM02 | F121: 121.46 | G121: =IF(LEFT(B121,1)="C","Credit","Factuur") | H121: =IF(AND(B121=B120,D121=D120,A121=A120,F121=F120),1,0) | I121: =IF(C121="C99999",1,0) | J121: =IF(OR(H121=1,I121=1),0,IF(G121="Credit",-F121,F121))
A122: 2026-07-02 | B122: F271988 | C122: C10617 | D122: SKU-10257 | E122: AM02 | F122: 113.76 | G122: =IF(LEFT(B122,1)="C","Credit","Factuur") | H122: =IF(AND(B122=B121,D122=D121,A122=A121,F122=F121),1,0) | I122: =IF(C122="C99999",1,0) | J122: =IF(OR(H122=1,I122=1),0,IF(G122="Credit",-F122,F122))
A123: 2026-07-02 | B123: F273218 | C123: C10690 | D123: SKU-10286 | E123: IS02 | F123: 146 | G123: =IF(LEFT(B123,1)="C","Credit","Factuur") | H123: =IF(AND(B123=B122,D123=D122,A123=A122,F123=F122),1,0) | I123: =IF(C123="C99999",1,0) | J123: =IF(OR(H123=1,I123=1),0,IF(G123="Credit",-F123,F123))
A124: 2026-07-02 | B124: F274260 | C124: C10754 | D124: SKU-10054 | E124: AM01 | F124: 271.71 | G124: =IF(LEFT(B124,1)="C","Credit","Factuur") | H124: =IF(AND(B124=B123,D124=D123,A124=A123,F124=F123),1,0) | I124: =IF(C124="C99999",1,0) | J124: =IF(OR(H124=1,I124=1),0,IF(G124="Credit",-F124,F124))
... A182: 2026-07-03 | B182: F261085 | C182: C10062 | D182: SKU-10259 | E182: AM05 | F182: 651.64 | G182: =IF(LEFT(B182,1)="C","Credit","Factuur") | H182: =IF(AND(B182=B181,D182=D181,A182=A181,F182=F181),1,0) | I182: =IF(C182="C99999",1,0) | J182: =IF(OR(H182=1,I182=1),0,IF(G182="Credit",-F182,F182))
A183: 2026-07-03 | B183: F261297 | C183: C10072 | D183: SKU-10074 | F183: 212.76 | G183: =IF(LEFT(B183,1)="C","Credit","Factuur") | H183: =IF(AND(B183=B182,D183=D182,A183=A182,F183=F182),1,0) | I183: =IF(C183="C99999",1,0) | J183: =IF(OR(H183=1,I183=1),0,IF(G183="Credit",-F183,F183))
A184: 2026-07-03 | B184: F261297 | C184: C10072 | D184: SKU-10116 | E184: AM08 | F184: 260.4 | G184: =IF(LEFT(B184,1)="C","Credit","Factuur") | H184: =IF(AND(B184=B183,D184=D183,A184=A183,F184=F183),1,0) | I184: =IF(C184="C99999",1,0) | J184: =IF(OR(H184=1,I184=1),0,IF(G184="Credit",-F184,F184))
A185: 2026-07-03 | B185: F261297 | C185: C10072 | D185: SKU-10278 | E185: AM08 | F185: 231.22 | G185: =IF(LEFT(B185,1)="C","Credit","Factuur") | H185: =IF(AND(B185=B184,D185=D184,A185=A184,F185=F184),1,0) | I185: =IF(C185="C99999",1,0) | J185: =IF(OR(H185=1,I185=1),0,IF(G185="Credit",-F185,F185))
A186: 2026-07-03 | B186: F261297 | C186: C10072 | D186: SKU-10289 | E186: AM08 | F186: 230.34 | G186: =IF(LEFT(B186,1)="C","Credit","Factuur") | H186: =IF(AND(B186=B185,D186=D185,A186=A185,F186=F185),1,0) | I186: =IF(C186="C99999",1,0) | J186: =IF(OR(H186=1,I186=1),0,IF(G186="Credit",-F186,F186))
A187: 2026-07-03 | B187: F261297 | C187: C10072 | D187: SKU-10321 | E187: AM08 | F187: 244.05 | G187: =IF(LEFT(B187,1)="C","Credit","Factuur") | H187: =IF(AND(B187=B186,D187=D186,A187=A186,F187=F186),1,0) | I187: =IF(C187="C99999",1,0) | J187: =IF(OR(H187=1,I187=1),0,IF(G187="Credit",-F187,F187))
A188: 2026-07-03 | B188: F261355 | C188: C10074 | D188: SKU-10061 | E188: AM06 | F188: 323.19 | G188: =IF(LEFT(B188,1)="C","Credit","Factuur") | H188: =IF(AND(B188=B187,D188=D187,A188=A187,F188=F187),1,0) | I188: =IF(C188="C99999",1,0) | J188: =IF(OR(H188=1,I188=1),0,IF(G188="Credit",-F188,F188))
A189: 2026-07-03 | B189: F261398 | C189: C10076 | D189: SKU-10211 | E189: AM02 | F189: 1734.26 | G189: =IF(LEFT(B189,1)="C","Credit","Factuur") | H189: =IF(AND(B189=B188,D189=D188,A189=A188,F189=F188),1,0) | I189: =IF(C189="C99999",1,0) | J189: =IF(OR(H189=1,I189=1),0,IF(G189="Credit",-F189,F189))
A190: 2026-07-03 | B190: F261796 | C190: C10095 | D190: SKU-10031 | E190: AM01 | F190: 262.53 | G190: =IF(LEFT(B190,1)="C","Credit","Factuur") | H190: =IF(AND(B190=B189,D190=D189,A190=A189,F190=F189),1,0) | I190: =IF(C190="C99999",1,0) | J190: =IF(OR(H190=1,I190=1),0,IF(G190="Credit",-F190,F190))
A191: 2026-07-03 | B191: F261796 | C191: C10095 | D191: SKU-10037 | E191: AM01 | F191: 237.21 | G191: =IF(LEFT(B191,1)="C","Credit","Factuur") | H191: =IF(AND(B191=B190,D191=D190,A191=A190,F191=F190),1,0) | I191: =IF(C191="C99999",1,0) | J191: =IF(OR(H191=1,I191=1),0,IF(G191="Credit",-F191,F191))
A192: 2026-07-03 | B192: F261796 | C192: C10095 | D192: SKU-10051 | E192: AM01 | F192: 256.4 | G192: =IF(LEFT(B192,1)="C","Credit","Factuur") | H192: =IF(AND(B192=B191,D192=D191,A192=A191,F192=F191),1,0) | I192: =IF(C192="C99999",1,0) | J192: =IF(OR(H192=1,I192=1),0,IF(G192="Credit",-F192,F192))
A193: 2026-07-03 | B193: F261796 | C193: C10095 | D193: SKU-10057 | E193: AM01 | F193: 247.5 | G193: =IF(LEFT(B193,1)="C","Credit","Factuur") | H193: =IF(AND(B193=B192,D193=D192,A193=A192,F193=F192),1,0) | I193: =IF(C193="C99999",1,0) | J193: =IF(OR(H193=1,I193=1),0,IF(G193="Credit",-F193,F193))
...

Sheet Finance
A1: Periode | B1: Grootboek | C1: Omschrijving | D1: Bedrag
A2: 2026-07 | B2: 700000 | C2: Omzet handelsgoederen | D2: 2008453.7
A3: 2026-08 | B3: 700000 | C3: Omzet handelsgoederen | D3: 1518877.8
A4: 2026-09 | B4: 700000 | C4: Omzet handelsgoederen | D4: 2414112.6
C5: Totaal Q3 | D5: =SUM(D2:D4)

Sheet Brug
A1: Stap | B1: Omschrijving | C1: Bedrag (Excel-formule) | D1: Rijen | E1: SQL-pipeline | F1: Controle
A2: 1 | B2: Wekelijks Excel-rapport (som van de export) | C2: =SUM(Export!$F$2:$F$10447) | D2: =COUNTA(Export!$B$2:$B$10447) | E2: 6339278 | F2: =IF(ROUND(C2-E2,2)=0,"OK","VERSCHIL")
A3: 2 | B3: Dubbel geëxporteerde dag eraf | C3: =-SUMIFS(Export!$F$2:$F$10447,Export!$H$2:$H$10447,1) | D3: =SUM(Export!$H$2:$H$10447) | E3: -110762.2 | F3: =IF(ROUND(C3-E3,2)=0,"OK","VERSCHIL")
A4: 3 | B4: Creditnota's: opgeteld i.p.v. afgetrokken (2×) | C4: =-2*SUMIFS(Export!$F$2:$F$10447,Export!$G$2:$G$10447,"Credit",Export!$H$2:$H$10447,0) | D4: =COUNTIFS(Export!$G$2:$G$10447,"Credit",Export!$H$2:$H$10447,0) | E4: -284980.24 | F4: =IF(ROUND(C4-E4,2)=0,"OK","VERSCHIL")
A5: 4 | B5: Personeelsshop (interne klant) eraf | C5: =-(SUMIFS(Export!$F$2:$F$10447,Export!$C$2:$C$10447,"C99999",Export!$G$2:$G$10447,"Factuur",Export!$H$2:$H$10447,0)-SUMIFS(Export!$F$2:$F$10447,Export!$C$2:$C$10447,"C99999",Export!$G$2:$G$10447,"Credit",Export!$H$2:$H$10447,0)) | D5: =COUNTIFS(Export!$C$2:$C$10447,"C99999",Export!$H$2:$H$10447,0) | E5: -2091.46 | F5: =IF(ROUND(C5-E5,2)=0,"OK","VERSCHIL")
A6: 5 | B6: Verklaard totaal | C6: =SUM(C2:C5) | E6: 5941444.1 | F6: =IF(ROUND(C6-E6,2)=0,"OK","VERSCHIL")
A7: 6 | B7: Finance (grootboek 700000) | C7: =Finance!D5 | E7: 5941444.1 | F7: =IF(ROUND(C7-E7,2)=0,"OK","VERSCHIL")
A8: 7 | B8: Onverklaard verschil | C8: =ROUND(C6-C7,2) | E8: 0 | F8: =IF(ROUND(C8-E8,2)=0,"OK","VERSCHIL")
A9: 8 | B9: Controle: som van kolom Netto op tab Export | C9: =SUM(Export!$J$2:$J$10447) | E9: 5941444.1 | F9: =IF(ROUND(C9-E9,2)=0,"OK","VERSCHIL")
B11: Kolom E is overgenomen uit data/metrics.json (SQL). Kolom C rekent Excel zelf uit.

Sheet Per verkoper
A1: Verkoper | B1: jul | C1: aug | D1: sep | E1: Q3
A2: AM01 | B2: =SUMIFS(Export!$J$2:$J$10447,Export!$E$2:$E$10447,"AM01",Export!$A$2:$A$10447,"2026-07*") | C2: =SUMIFS(Export!$J$2:$J$10447,Export!$E$2:$E$10447,"AM01",Export!$A$2:$A$10447,"2026-08*") | D2: =SUMIFS(Export!$J$2:$J$10447,Export!$E$2:$E$10447,"AM01",Export!$A$2:$A$10447,"2026-09*") | E2: =SUM(B2:D2)
A3: AM02 | B3: =SUMIFS(Export!$J$2:$J$10447,Export!$E$2:$E$10447,"AM02",Export!$A$2:$A$10447,"2026-07*") | C3: =SUMIFS(Export!$J$2:$J$10447,Export!$E$2:$E$10447,"AM02",Export!$A$2:$A$10447,"2026-08*") | D3: =SUMIFS(Export!$J$2:$J$10447,Export!$E$2:$E$10447,"AM02",Export!$A$2:$A$10447,"2026-09*") | E3: =SUM(B3:D3)
A4: AM03 | B4: =SUMIFS(Export!$J$2:$J$10447,Export!$E$2:$E$10447,"AM03",Export!$A$2:$A$10447,"2026-07*") | C4: =SUMIFS(Export!$J$2:$J$10447,Export!$E$2:$E$10447,"AM03",Export!$A$2:$A$10447,"2026-08*") | D4: =SUMIFS(Export!$J$2:$J$10447,Export!$E$2:$E$10447,"AM03",Export!$A$2:$A$10447,"2026-09*") | E4: =SUM(B4:D4)
A5: AM05 | B5: =SUMIFS(Export!$J$2:$J$10447,Export!$E$2:$E$10447,"AM05",Export!$A$2:$A$10447,"2026-07*") | C5: =SUMIFS(Export!$J$2:$J$10447,Export!$E$2:$E$10447,"AM05",Export!$A$2:$A$10447,"2026-08*") | D5: =SUMIFS(Export!$J$2:$J$10447,Export!$E$2:$E$10447,"AM05",Export!$A$2:$A$10447,"2026-09*") | E5: =SUM(B5:D5)
A6: AM06 | B6: =SUMIFS(Export!$J$2:$J$10447,Export!$E$2:$E$10447,"AM06",Export!$A$2:$A$10447,"2026-07*") | C6: =SUMIFS(Export!$J$2:$J$10447,Export!$E$2:$E$10447,"AM06",Export!$A$2:$A$10447,"2026-08*") | D6: =SUMIFS(Export!$J$2:$J$10447,Export!$E$2:$E$10447,"AM06",Export!$A$2:$A$10447,"2026-09*") | E6: =SUM(B6:D6)
A7: AM07 | B7: =SUMIFS(Export!$J$2:$J$10447,Export!$E$2:$E$10447,"AM07",Export!$A$2:$A$10447,"2026-07*") | C7: =SUMIFS(Export!$J$2:$J$10447,Export!$E$2:$E$10447,"AM07",Export!$A$2:$A$10447,"2026-08*") | D7: =SUMIFS(Export!$J$2:$J$10447,Export!$E$2:$E$10447,"AM07",Export!$A$2:$A$10447,"2026-09*") | E7: =SUM(B7:D7)
A8: AM08 | B8: =SUMIFS(Export!$J$2:$J$10447,Export!$E$2:$E$10447,"AM08",Export!$A$2:$A$10447,"2026-07*") | C8: =SUMIFS(Export!$J$2:$J$10447,Export!$E$2:$E$10447,"AM08",Export!$A$2:$A$10447,"2026-08*") | D8: =SUMIFS(Export!$J$2:$J$10447,Export!$E$2:$E$10447,"AM08",Export!$A$2:$A$10447,"2026-09*") | E8: =SUM(B8:D8)
A9: AM09 | B9: =SUMIFS(Export!$J$2:$J$10447,Export!$E$2:$E$10447,"AM09",Export!$A$2:$A$10447,"2026-07*") | C9: =SUMIFS(Export!$J$2:$J$10447,Export!$E$2:$E$10447,"AM09",Export!$A$2:$A$10447,"2026-08*") | D9: =SUMIFS(Export!$J$2:$J$10447,Export!$E$2:$E$10447,"AM09",Export!$A$2:$A$10447,"2026-09*") | E9: =SUM(B9:D9)
A10: AM11 | B10: =SUMIFS(Export!$J$2:$J$10447,Export!$E$2:$E$10447,"AM11",Export!$A$2:$A$10447,"2026-07*") | C10: =SUMIFS(Export!$J$2:$J$10447,Export!$E$2:$E$10447,"AM11",Export!$A$2:$A$10447,"2026-08*") | D10: =SUMIFS(Export!$J$2:$J$10447,Export!$E$2:$E$10447,"AM11",Export!$A$2:$A$10447,"2026-09*") | E10: =SUM(B10:D10)
A11: AM12 | B11: =SUMIFS(Export!$J$2:$J$10447,Export!$E$2:$E$10447,"AM12",Export!$A$2:$A$10447,"2026-07*") | C11: =SUMIFS(Export!$J$2:$J$10447,Export!$E$2:$E$10447,"AM12",Export!$A$2:$A$10447,"2026-08*") | D11: =SUMIFS(Export!$J$2:$J$10447,Export!$E$2:$E$10447,"AM12",Export!$A$2:$A$10447,"2026-09*") | E11: =SUM(B11:D11)
A12: IS01 | B12: =SUMIFS(Export!$J$2:$J$10447,Export!$E$2:$E$10447,"IS01",Export!$A$2:$A$10447,"2026-07*") | C12: =SUMIFS(Export!$J$2:$J$10447,Export!$E$2:$E$10447,"IS01",Export!$A$2:$A$10447,"2026-08*") | D12: =SUMIFS(Export!$J$2:$J$10447,Export!$E$2:$E$10447,"IS01",Export!$A$2:$A$10447,"2026-09*") | E12: =SUM(B12:D12)
A13: IS02 | B13: =SUMIFS(Export!$J$2:$J$10447,Export!$E$2:$E$10447,"IS02",Export!$A$2:$A$10447,"2026-07*") | C13: =SUMIFS(Export!$J$2:$J$10447,Export!$E$2:$E$10447,"IS02",Export!$A$2:$A$10447,"2026-08*") | D13: =SUMIFS(Export!$J$2:$J$10447,Export!$E$2:$E$10447,"IS02",Export!$A$2:$A$10447,"2026-09*") | E13: =SUM(B13:D13)
A14: (leeg = niet toegewezen) | B14: =SUMIFS(Export!$J$2:$J$10447,Export!$E$2:$E$10447,"",Export!$A$2:$A$10447,"2026-07*") | C14: =SUMIFS(Export!$J$2:$J$10447,Export!$E$2:$E$10447,"",Export!$A$2:$A$10447,"2026-08*") | D14: =SUMIFS(Export!$J$2:$J$10447,Export!$E$2:$E$10447,"",Export!$A$2:$A$10447,"2026-09*") | E14: =SUM(B14:D14)
A15: Totaal | B15: =SUM(B2:B14) | C15: =SUM(C2:C14) | D15: =SUM(D2:D14) | E15: =SUM(E2:E14)
A17: Datums staan als tekst (JJJJ-MM-DD), daarom filtert "2026-07*" op juli. Lege verkoper: in het datawarehouse krijgt die lijn de verkoper op factuurdatum (regel ERP-01).
